2020-09-16 04:44:28,464 INFO    MainThread:1189 [internal.py:wandb_internal():62] W&B internal server running at pid: 1189
2020-09-16 04:44:28,511 DEBUG   HandlerThread:1189 [handler.py:handle():47] handle: request
2020-09-16 04:44:28,516 DEBUG   HandlerThread:1189 [handler.py:handle_request():56] handle_request: login
2020-09-16 04:44:28,525 DEBUG   SenderThread:1189 [sender.py:send():89] send: request
2020-09-16 04:44:28,604 DEBUG   SenderThread:1189 [connectionpool.py:_new_conn():959] Starting new HTTPS connection (1): api.wandb.ai:443
2020-09-16 04:44:28,980 DEBUG   SenderThread:1189 [connectionpool.py:_make_request():437] https://api.wandb.ai:443 "POST /graphql HTTP/1.1" 200 None
2020-09-16 04:44:28,982 INFO    SenderThread:1189 [sender.py:send_request_login():135] Login server info: {'cliVersionInfo': {'min_cli_version': '0.8.20', 'max_cli_version': '0.10.0rc8'}}
2020-09-16 04:44:28,986 DEBUG   HandlerThread:1189 [handler.py:handle():47] handle: header
2020-09-16 04:44:28,986 DEBUG   SenderThread:1189 [sender.py:send():89] send: header
2020-09-16 04:44:28,986 DEBUG   HandlerThread:1189 [handler.py:handle():47] handle: request
2020-09-16 04:44:28,986 INFO    WriterThread:1189 [datastore.py:open_for_write():76] open: wandb/run-20200916_044424-2bicks63/run-2bicks63.wandb
2020-09-16 04:44:28,987 DEBUG   HandlerThread:1189 [handler.py:handle_request():56] handle_request: check_version
2020-09-16 04:44:28,989 DEBUG   HandlerThread:1189 [connectionpool.py:_new_conn():959] Starting new HTTPS connection (1): pypi.org:443
2020-09-16 04:44:29,197 DEBUG   HandlerThread:1189 [connectionpool.py:_make_request():437] https://pypi.org:443 "GET /pypi/wandb/json HTTP/1.1" 200 48774
2020-09-16 04:44:29,207 DEBUG   HandlerThread:1189 [handler.py:handle():47] handle: run
2020-09-16 04:44:29,207 DEBUG   SenderThread:1189 [sender.py:send():89] send: run
2020-09-16 04:44:29,210 DEBUG   SenderThread:1189 [cmd.py:execute():719] Popen(['git', 'cat-file', '--batch-check'], cwd=/pvol/hzwa180/data-processing, universal_newlines=False, shell=None, istream=<valid stream>)
2020-09-16 04:44:29,235 DEBUG   SenderThread:1189 [connectionpool.py:_new_conn():959] Starting new HTTPS connection (1): api.wandb.ai:443
2020-09-16 04:44:29,569 DEBUG   SenderThread:1189 [connectionpool.py:_make_request():437] https://api.wandb.ai:443 "POST /graphql HTTP/1.1" 404 None
2020-09-16 04:44:29,571 ERROR   SenderThread:1189 [internal_api.py:execute():118] 404 response executing GraphQL.
2020-09-16 04:44:29,571 ERROR   SenderThread:1189 [internal_api.py:execute():119] {"errors":[{"message":"entity run_1 not found during upsertBucket","path":["upsertBucket"]}],"data":{"upsertBucket":null}}
2020-09-16 04:44:30,208 INFO    HandlerThread:1189 [handler.py:finish():274] shutting down handler
2020-09-16 04:44:30,209 INFO    WriterThread:1189 [datastore.py:close():257] close: wandb/run-20200916_044424-2bicks63/run-2bicks63.wandb
2020-09-16 04:44:30,526 ERROR   MainThread:1189 [internal.py:wandb_internal():128] Thread SenderThread:
Traceback (most recent call last):
  File "/opt/anaconda3/envs/henry/lib/python3.7/site-packages/wandb/old/retry.py", line 96, in __call__
    result = self._call_fn(*args, **kwargs)
  File "/opt/anaconda3/envs/henry/lib/python3.7/site-packages/wandb/internal/internal_api.py", line 121, in execute
    six.reraise(*sys.exc_info())
  File "/opt/anaconda3/envs/henry/lib/python3.7/site-packages/six.py", line 703, in reraise
    raise value
  File "/opt/anaconda3/envs/henry/lib/python3.7/site-packages/wandb/internal/internal_api.py", line 115, in execute
    return self.client.execute(*args, **kwargs)
  File "/opt/anaconda3/envs/henry/lib/python3.7/site-packages/wandb/vendor/gql-0.2.0/gql/client.py", line 52, in execute
    result = self._get_result(document, *args, **kwargs)
  File "/opt/anaconda3/envs/henry/lib/python3.7/site-packages/wandb/vendor/gql-0.2.0/gql/client.py", line 60, in _get_result
    return self.transport.execute(document, *args, **kwargs)
  File "/opt/anaconda3/envs/henry/lib/python3.7/site-packages/wandb/vendor/gql-0.2.0/gql/transport/requests.py", line 39, in execute
    request.raise_for_status()
  File "/opt/anaconda3/envs/henry/lib/python3.7/site-packages/requests/models.py", line 941, in raise_for_status
    raise HTTPError(http_error_msg, response=self)
requests.exceptions.HTTPError: 404 Client Error: Not Found for url: https://api.wandb.ai/graphql

During handling of the above exception, another exception occurred:

Traceback (most recent call last):
  File "/opt/anaconda3/envs/henry/lib/python3.7/site-packages/wandb/apis/normalize.py", line 25, in wrapper
    return func(*args, **kwargs)
  File "/opt/anaconda3/envs/henry/lib/python3.7/site-packages/wandb/internal/internal_api.py", line 839, in upsert_run
    mutation, variable_values=variable_values, **kwargs)
  File "/opt/anaconda3/envs/henry/lib/python3.7/site-packages/wandb/old/retry.py", line 105, in __call__
    if not check_retry_fn(e):
  File "/opt/anaconda3/envs/henry/lib/python3.7/site-packages/wandb/util.py", line 574, in no_retry_auth
    raise CommError("Permission denied, ask the project owner to grant you access")
wandb.errors.error.CommError: Permission denied, ask the project owner to grant you access

During handling of the above exception, another exception occurred:

Traceback (most recent call last):
  File "/opt/anaconda3/envs/henry/lib/python3.7/site-packages/wandb/internal/internal_util.py", line 33, in run
    self._run()
  File "/opt/anaconda3/envs/henry/lib/python3.7/site-packages/wandb/internal/internal_util.py", line 60, in _run
    self._process(record)
  File "/opt/anaconda3/envs/henry/lib/python3.7/site-packages/wandb/internal/internal.py", line 232, in _process
    self._sm.send(record)
  File "/opt/anaconda3/envs/henry/lib/python3.7/site-packages/wandb/internal/sender.py", line 91, in send
    send_handler(record)
  File "/opt/anaconda3/envs/henry/lib/python3.7/site-packages/wandb/internal/sender.py", line 344, in send_run
    commit=repo.last_commit,
  File "/opt/anaconda3/envs/henry/lib/python3.7/site-packages/wandb/apis/normalize.py", line 57, in wrapper
    message, err), sys.exc_info()[2])
  File "/opt/anaconda3/envs/henry/lib/python3.7/site-packages/six.py", line 702, in reraise
    raise value.with_traceback(tb)
  File "/opt/anaconda3/envs/henry/lib/python3.7/site-packages/wandb/apis/normalize.py", line 25, in wrapper
    return func(*args, **kwargs)
  File "/opt/anaconda3/envs/henry/lib/python3.7/site-packages/wandb/internal/internal_api.py", line 839, in upsert_run
    mutation, variable_values=variable_values, **kwargs)
  File "/opt/anaconda3/envs/henry/lib/python3.7/site-packages/wandb/old/retry.py", line 105, in __call__
    if not check_retry_fn(e):
  File "/opt/anaconda3/envs/henry/lib/python3.7/site-packages/wandb/util.py", line 574, in no_retry_auth
    raise CommError("Permission denied, ask the project owner to grant you access")
wandb.errors.error.CommError: Permission denied, ask the project owner to grant you access
2020-09-16 04:44:30,574 INFO    MainThread:1189 [internal.py:handle_exit():137] Internal process exited
